Workbook
Name Slicer_Category: #N/A
Name Slicer_Category1: #N/A
Name Timeline_Invoice_Date: #N/A
Name Timeline_Invoice_Date1: #N/A

Sheet Purchase_Data
A1: Purchase_ID | B1: Purchase_Date | C1: Month | D1: Supplier_Name | E1: Category | F1: Product_Name | G1: Payment | H1: Quantity_Purchased | I1: Purchase_Rate | J1: Purchase_Amount
A2: P0001 | B2: 45432 | C2: =TEXT(B2,"mmmm") -> May | D2: Nestle Partners | E2: Decor | F2: Wall Frame | G2: Offline | H2: 62 | I2: 399 | J2: 24738
A3: P0002 | B3: 45638 | C3: =TEXT(B3,"mmmm") -> December | D3: Coca Cola Supply | E3: Snacks | F3: Namkeen Mix | G3: Online | H3: 427 | I3: 72 | J3: 30744
A4: P0003 | B4: 45339 | C4: =TEXT(B4,"mmmm") -> February | D4: Nestle Partners | E4: Dairy | F4: Cheese Slices | G4: Online | H4: 66 | I4: 35 | J4: 2310
A5: P0004 | B5: 45624 | C5: =TEXT(B5,"mmmm") -> November | D5: Coca Cola Supply | E5: Snacks | F5: Potato Chips | G5: Online | H5: 337 | I5: 121 | J5: 40777
A6: P0005 | B6: 45434 | C6: =TEXT(B6,"mmmm") -> May | D6: Amul Distributors | E6: Kitchen | F6: Spices Pack | G6: Online | H6: 279 | I6: 321 | J6: 89559
A7: P0006 | B7: 45466 | C7: =TEXT(B7,"mmmm") -> June | D7: Britannia Supply | E7: Handloom | F7: Cotton Bedsheet | G7: Offline | H7: 407 | I7: 236 | J7: 96052
A8: P0007 | B8: 45344 | C8: =TEXT(B8,"mmmm") -> February | D8: HUL Wholesale | E8: Snacks | F8: Namkeen Mix | G8: Offline | H8: 440 | I8: 192 | J8: 84480
A9: P0008 | B9: 45468 | C9: =TEXT(B9,"mmmm") -> June | D9: Regional FMCG Hub | E9: Kitchen | F9: Cooking Oil 1L | G9: Online | H9: 233 | I9: 453 | J9: 105549
A10: P0009 | B10: 45566 | C10: =TEXT(B10,"mmmm") -> October | D10: HUL Wholesale | E10: Beverages | F10: Cola 1L | G10: Online | H10: 423 | I10: 255 | J10: 107865
A11: P0010 | B11: 45613 | C11: =TEXT(B11,"mmmm") -> November | D11: Regional FMCG Hub | E11: Kitchen | F11: Cooking Oil 1L | G11: Online | H11: 332 | I11: 170 | J11: 56440
A12: P0011 | B12: 45652 | C12: =TEXT(B12,"mmmm") -> December | D12: HUL Wholesale | E12: Handloom | F12: Hand Towel | G12: Online | H12: 345 | I12: 118 | J12: 40710
A13: P0012 | B13: 45332 | C13: =TEXT(B13,"mmmm") -> February | D13: Nestle Partners | E13: Dairy | F13: Curd 500g | G13: Offline | H13: 445 | I13: 168 | J13: 74760
... A301: P0300 | B301: 45580 | C301: =TEXT(B301,"mmmm") -> October | D301: Regional FMCG Hub | E301: Snacks | F301: Cookies | G301: Online | H301: 287 | I301: 406 | J301: 116522

Sheet Purchase Manual Reports
A1: S no | B1: Supplier Name | C1: Amount | D1: January | E1: February | F1: March | G1: April | H1: May | I1: June | J1: July | K1: August | L1: September | M1: October | N1: November | O1: December
A2: 1 | B2: Nestle Partners | C2: =SUMIF(Purchase_Data!$D$2:$D$301,B2:B11,Purchase_Data!$J$2:$J$301) -> 1876719 | D2: =SUMIFS(Purchase_Data!$J$2:$J$301,Purchase_Data!$D$2:$D$301,$B$2:$B$11,Purchase_Data!$C$2:$C$301,$D$1:$O$1) -> 197840 | E2: =SUMIFS(Purchase_Data!$J$2:$J$301,Purchase_Data!$D$2:$D$301,$B$2:$B$11,Purchase_Data!$C$2:$C$301,$D$1:$O$1) -> 589355 | F2: =SUMIFS(Purchase_Data!$J$2:$J$301,Purchase_Data!$D$2:$D$301,$B$2:$B$11,Purchase_Data!$C$2:$C$301,$D$1:$O$1) -> 0 | G2: =SUMIFS(Purchase_Data!$J$2:$J$301,Purchase_Data!$D$2:$D$301,$B$2:$B$11,Purchase_Data!$C$2:$C$301,$D$1:$O$1) -> 99510 | H2: =SUMIFS(Purchase_Data!$J$2:$J$301,Purchase_Data!$D$2:$D$301,$B$2:$B$11,Purchase_Data!$C$2:$C$301,$D$1:$O$1) -> 193410 | I2: =SUMIFS(Purchase_Data!$J$2:$J$301,Purchase_Data!$D$2:$D$301,$B$2:$B$11,Purchase_Data!$C$2:$C$301,$D$1:$O$1) -> 159120 | J2: =SUMIFS(Purchase_Data!$J$2:$J$301,Purchase_Data!$D$2:$D$301,$B$2:$B$11,Purchase_Data!$C$2:$C$301,$D$1:$O$1) -> 199273 | K2: =SUMIFS(Purchase_Data!$J$2:$J$301,Purchase_Data!$D$2:$D$301,$B$2:$B$11,Purchase_Data!$C$2:$C$301,$D$1:$O$1) -> 70848 | ... O2: =SUMIFS(Purchase_Data!$J$2:$J$301,Purchase_Data!$D$2:$D$301,$B$2:$B$11,Purchase_Data!$C$2:$C$301,$D$1:$O$1) -> 74529
A3: 2 | B3: Coca Cola Supply | C3: =SUMIF(Purchase_Data!$D$2:$D$301,B3:B12,Purchase_Data!$J$2:$J$301) -> 1980707 | D3: =SUMIFS(Purchase_Data!$J$2:$J$301,Purchase_Data!$D$2:$D$301,$B$2:$B$11,Purchase_Data!$C$2:$C$301,$D$1:$O$1) -> 139236 | E3: =SUMIFS(Purchase_Data!$J$2:$J$301,Purchase_Data!$D$2:$D$301,$B$2:$B$11,Purchase_Data!$C$2:$C$301,$D$1:$O$1) -> 441278 | F3: =SUMIFS(Purchase_Data!$J$2:$J$301,Purchase_Data!$D$2:$D$301,$B$2:$B$11,Purchase_Data!$C$2:$C$301,$D$1:$O$1) -> 0 | G3: =SUMIFS(Purchase_Data!$J$2:$J$301,Purchase_Data!$D$2:$D$301,$B$2:$B$11,Purchase_Data!$C$2:$C$301,$D$1:$O$1) -> 194202 | H3: =SUMIFS(Purchase_Data!$J$2:$J$301,Purchase_Data!$D$2:$D$301,$B$2:$B$11,Purchase_Data!$C$2:$C$301,$D$1:$O$1) -> 118938 | I3: =SUMIFS(Purchase_Data!$J$2:$J$301,Purchase_Data!$D$2:$D$301,$B$2:$B$11,Purchase_Data!$C$2:$C$301,$D$1:$O$1) -> 41752 | J3: =SUMIFS(Purchase_Data!$J$2:$J$301,Purchase_Data!$D$2:$D$301,$B$2:$B$11,Purchase_Data!$C$2:$C$301,$D$1:$O$1) -> 278965 | K3: =SUMIFS(Purchase_Data!$J$2:$J$301,Purchase_Data!$D$2:$D$301,$B$2:$B$11,Purchase_Data!$C$2:$C$301,$D$1:$O$1) -> 162584 | ... O3: =SUMIFS(Purchase_Data!$J$2:$J$301,Purchase_Data!$D$2:$D$301,$B$2:$B$11,Purchase_Data!$C$2:$C$301,$D$1:$O$1) -> 46032
A4: 3 | B4: Amul Distributors | C4: =SUMIF(Purchase_Data!$D$2:$D$301,B4:B13,Purchase_Data!$J$2:$J$301) -> 1163176 | D4: =SUMIFS(Purchase_Data!$J$2:$J$301,Purchase_Data!$D$2:$D$301,$B$2:$B$11,Purchase_Data!$C$2:$C$301,$D$1:$O$1) -> 164619 | E4: =SUMIFS(Purchase_Data!$J$2:$J$301,Purchase_Data!$D$2:$D$301,$B$2:$B$11,Purchase_Data!$C$2:$C$301,$D$1:$O$1) -> 0 | F4: =SUMIFS(Purchase_Data!$J$2:$J$301,Purchase_Data!$D$2:$D$301,$B$2:$B$11,Purchase_Data!$C$2:$C$301,$D$1:$O$1) -> 56282 | G4: =SUMIFS(Purchase_Data!$J$2:$J$301,Purchase_Data!$D$2:$D$301,$B$2:$B$11,Purchase_Data!$C$2:$C$301,$D$1:$O$1) -> 0 | H4: =SUMIFS(Purchase_Data!$J$2:$J$301,Purchase_Data!$D$2:$D$301,$B$2:$B$11,Purchase_Data!$C$2:$C$301,$D$1:$O$1) -> 95881 | I4: =SUMIFS(Purchase_Data!$J$2:$J$301,Purchase_Data!$D$2:$D$301,$B$2:$B$11,Purchase_Data!$C$2:$C$301,$D$1:$O$1) -> 58536 | J4: =SUMIFS(Purchase_Data!$J$2:$J$301,Purchase_Data!$D$2:$D$301,$B$2:$B$11,Purchase_Data!$C$2:$C$301,$D$1:$O$1) -> 131228 | K4: =SUMIFS(Purchase_Data!$J$2:$J$301,Purchase_Data!$D$2:$D$301,$B$2:$B$11,Purchase_Data!$C$2:$C$301,$D$1:$O$1) -> 0 | ... O4: =SUMIFS(Purchase_Data!$J$2:$J$301,Purchase_Data!$D$2:$D$301,$B$2:$B$11,Purchase_Data!$C$2:$C$301,$D$1:$O$1) -> 0
A5: 4 | B5: Britannia Supply | C5: =SUMIF(Purchase_Data!$D$2:$D$301,B5:B14,Purchase_Data!$J$2:$J$301) -> 2597333 | D5: =SUMIFS(Purchase_Data!$J$2:$J$301,Purchase_Data!$D$2:$D$301,$B$2:$B$11,Purchase_Data!$C$2:$C$301,$D$1:$O$1) -> 132810 | E5: =SUMIFS(Purchase_Data!$J$2:$J$301,Purchase_Data!$D$2:$D$301,$B$2:$B$11,Purchase_Data!$C$2:$C$301,$D$1:$O$1) -> 475737 | F5: =SUMIFS(Purchase_Data!$J$2:$J$301,Purchase_Data!$D$2:$D$301,$B$2:$B$11,Purchase_Data!$C$2:$C$301,$D$1:$O$1) -> 335293 | G5: =SUMIFS(Purchase_Data!$J$2:$J$301,Purchase_Data!$D$2:$D$301,$B$2:$B$11,Purchase_Data!$C$2:$C$301,$D$1:$O$1) -> 192788 | H5: =SUMIFS(Purchase_Data!$J$2:$J$301,Purchase_Data!$D$2:$D$301,$B$2:$B$11,Purchase_Data!$C$2:$C$301,$D$1:$O$1) -> 277710 | I5: =SUMIFS(Purchase_Data!$J$2:$J$301,Purchase_Data!$D$2:$D$301,$B$2:$B$11,Purchase_Data!$C$2:$C$301,$D$1:$O$1) -> 193345 | J5: =SUMIFS(Purchase_Data!$J$2:$J$301,Purchase_Data!$D$2:$D$301,$B$2:$B$11,Purchase_Data!$C$2:$C$301,$D$1:$O$1) -> 102702 | K5: =SUMIFS(Purchase_Data!$J$2:$J$301,Purchase_Data!$D$2:$D$301,$B$2:$B$11,Purchase_Data!$C$2:$C$301,$D$1:$O$1) -> 441363 | ... O5: =SUMIFS(Purchase_Data!$J$2:$J$301,Purchase_Data!$D$2:$D$301,$B$2:$B$11,Purchase_Data!$C$2:$C$301,$D$1:$O$1) -> 234394
A6: 5 | B6: HUL Wholesale | C6: =SUMIF(Purchase_Data!$D$2:$D$301,B6:B15,Purchase_Data!$J$2:$J$301) -> 2598468 | D6: =SUMIFS(Purchase_Data!$J$2:$J$301,Purchase_Data!$D$2:$D$301,$B$2:$B$11,Purchase_Data!$C$2:$C$301,$D$1:$O$1) -> 400582 | E6: =SUMIFS(Purchase_Data!$J$2:$J$301,Purchase_Data!$D$2:$D$301,$B$2:$B$11,Purchase_Data!$C$2:$C$301,$D$1:$O$1) -> 259128 | F6: =SUMIFS(Purchase_Data!$J$2:$J$301,Purchase_Data!$D$2:$D$301,$B$2:$B$11,Purchase_Data!$C$2:$C$301,$D$1:$O$1) -> 332704 | G6: =SUMIFS(Purchase_Data!$J$2:$J$301,Purchase_Data!$D$2:$D$301,$B$2:$B$11,Purchase_Data!$C$2:$C$301,$D$1:$O$1) -> 113864 | H6: =SUMIFS(Purchase_Data!$J$2:$J$301,Purchase_Data!$D$2:$D$301,$B$2:$B$11,Purchase_Data!$C$2:$C$301,$D$1:$O$1) -> 161975 | I6: =SUMIFS(Purchase_Data!$J$2:$J$301,Purchase_Data!$D$2:$D$301,$B$2:$B$11,Purchase_Data!$C$2:$C$301,$D$1:$O$1) -> 436966 | J6: =SUMIFS(Purchase_Data!$J$2:$J$301,Purchase_Data!$D$2:$D$301,$B$2:$B$11,Purchase_Data!$C$2:$C$301,$D$1:$O$1) -> 201746 | K6: =SUMIFS(Purchase_Data!$J$2:$J$301,Purchase_Data!$D$2:$D$301,$B$2:$B$11,Purchase_Data!$C$2:$C$301,$D$1:$O$1) -> 0 | ... O6: =SUMIFS(Purchase_Data!$J$2:$J$301,Purchase_Data!$D$2:$D$301,$B$2:$B$11,Purchase_Data!$C$2:$C$301,$D$1:$O$1) -> 219822
A7: 6 | B7: Regional FMCG Hub | C7: =SUMIF(Purchase_Data!$D$2:$D$301,B7:B16,Purchase_Data!$J$2:$J$301) -> 2566552 | D7: =SUMIFS(Purchase_Data!$J$2:$J$301,Purchase_Data!$D$2:$D$301,$B$2:$B$11,Purchase_Data!$C$2:$C$301,$D$1:$O$1) -> 26331 | E7: =SUMIFS(Purchase_Data!$J$2:$J$301,Purchase_Data!$D$2:$D$301,$B$2:$B$11,Purchase_Data!$C$2:$C$301,$D$1:$O$1) -> 124880 | F7: =SUMIFS(Purchase_Data!$J$2:$J$301,Purchase_Data!$D$2:$D$301,$B$2:$B$11,Purchase_Data!$C$2:$C$301,$D$1:$O$1) -> 251771 | G7: =SUMIFS(Purchase_Data!$J$2:$J$301,Purchase_Data!$D$2:$D$301,$B$2:$B$11,Purchase_Data!$C$2:$C$301,$D$1:$O$1) -> 242748 | H7: =SUMIFS(Purchase_Data!$J$2:$J$301,Purchase_Data!$D$2:$D$301,$B$2:$B$11,Purchase_Data!$C$2:$C$301,$D$1:$O$1) -> 329284 | I7: =SUMIFS(Purchase_Data!$J$2:$J$301,Purchase_Data!$D$2:$D$301,$B$2:$B$11,Purchase_Data!$C$2:$C$301,$D$1:$O$1) -> 227879 | J7: =SUMIFS(Purchase_Data!$J$2:$J$301,Purchase_Data!$D$2:$D$301,$B$2:$B$11,Purchase_Data!$C$2:$C$301,$D$1:$O$1) -> 52018 | K7: =SUMIFS(Purchase_Data!$J$2:$J$301,Purchase_Data!$D$2:$D$301,$B$2:$B$11,Purchase_Data!$C$2:$C$301,$D$1:$O$1) -> 167440 | ... O7: =SUMIFS(Purchase_Data!$J$2:$J$301,Purchase_Data!$D$2:$D$301,$B$2:$B$11,Purchase_Data!$C$2:$C$301,$D$1:$O$1) -> 0
A8: 7 | B8: Local Handloom Co | C8: =SUMIF(Purchase_Data!$D$2:$D$301,B8:B17,Purchase_Data!$J$2:$J$301) -> 1729054 | D8: =SUMIFS(Purchase_Data!$J$2:$J$301,Purchase_Data!$D$2:$D$301,$B$2:$B$11,Purchase_Data!$C$2:$C$301,$D$1:$O$1) -> 0 | E8: =SUMIFS(Purchase_Data!$J$2:$J$301,Purchase_Data!$D$2:$D$301,$B$2:$B$11,Purchase_Data!$C$2:$C$301,$D$1:$O$1) -> 240320 | F8: =SUMIFS(Purchase_Data!$J$2:$J$301,Purchase_Data!$D$2:$D$301,$B$2:$B$11,Purchase_Data!$C$2:$C$301,$D$1:$O$1) -> 47895 | G8: =SUMIFS(Purchase_Data!$J$2:$J$301,Purchase_Data!$D$2:$D$301,$B$2:$B$11,Purchase_Data!$C$2:$C$301,$D$1:$O$1) -> 53852 | H8: =SUMIFS(Purchase_Data!$J$2:$J$301,Purchase_Data!$D$2:$D$301,$B$2:$B$11,Purchase_Data!$C$2:$C$301,$D$1:$O$1) -> 48953 | I8: =SUMIFS(Purchase_Data!$J$2:$J$301,Purchase_Data!$D$2:$D$301,$B$2:$B$11,Purchase_Data!$C$2:$C$301,$D$1:$O$1) -> 123843 | J8: =SUMIFS(Purchase_Data!$J$2:$J$301,Purchase_Data!$D$2:$D$301,$B$2:$B$11,Purchase_Data!$C$2:$C$301,$D$1:$O$1) -> 74285 | K8: =SUMIFS(Purchase_Data!$J$2:$J$301,Purchase_Data!$D$2:$D$301,$B$2:$B$11,Purchase_Data!$C$2:$C$301,$D$1:$O$1) -> 373841 | ... O8: =SUMIFS(Purchase_Data!$J$2:$J$301,Purchase_Data!$D$2:$D$301,$B$2:$B$11,Purchase_Data!$C$2:$C$301,$D$1:$O$1) -> 100584
A9: 8 | B9: ITC Trade Corp | C9: =SUMIF(Purchase_Data!$D$2:$D$301,B9:B18,Purchase_Data!$J$2:$J$301) -> 2093283 | D9: =SUMIFS(Purchase_Data!$J$2:$J$301,Purchase_Data!$D$2:$D$301,$B$2:$B$11,Purchase_Data!$C$2:$C$301,$D$1:$O$1) -> 34671 | E9: =SUMIFS(Purchase_Data!$J$2:$J$301,Purchase_Data!$D$2:$D$301,$B$2:$B$11,Purchase_Data!$C$2:$C$301,$D$1:$O$1) -> 153708 | F9: =SUMIFS(Purchase_Data!$J$2:$J$301,Purchase_Data!$D$2:$D$301,$B$2:$B$11,Purchase_Data!$C$2:$C$301,$D$1:$O$1) -> 19886 | G9: =SUMIFS(Purchase_Data!$J$2:$J$301,Purchase_Data!$D$2:$D$301,$B$2:$B$11,Purchase_Data!$C$2:$C$301,$D$1:$O$1) -> 244054 | H9: =SUMIFS(Purchase_Data!$J$2:$J$301,Purchase_Data!$D$2:$D$301,$B$2:$B$11,Purchase_Data!$C$2:$C$301,$D$1:$O$1) -> 372919 | I9: =SUMIFS(Purchase_Data!$J$2:$J$301,Purchase_Data!$D$2:$D$301,$B$2:$B$11,Purchase_Data!$C$2:$C$301,$D$1:$O$1) -> 0 | J9: =SUMIFS(Purchase_Data!$J$2:$J$301,Purchase_Data!$D$2:$D$301,$B$2:$B$11,Purchase_Data!$C$2:$C$301,$D$1:$O$1) -> 508968 | K9: =SUMIFS(Purchase_Data!$J$2:$J$301,Purchase_Data!$D$2:$D$301,$B$2:$B$11,Purchase_Data!$C$2:$C$301,$D$1:$O$1) -> 112172 | ... O9: =SUMIFS(Purchase_Data!$J$2:$J$301,Purchase_Data!$D$2:$D$301,$B$2:$B$11,Purchase_Data!$C$2:$C$301,$D$1:$O$1) -> 0
A10: 9 | B10: Tata Consumer Trade | C10: =SUMIF(Purchase_Data!$D$2:$D$301,B10:B19,Purchase_Data!$J$2:$J$301) -> 2151913 | D10: =SUMIFS(Purchase_Data!$J$2:$J$301,Purchase_Data!$D$2:$D$301,$B$2:$B$11,Purchase_Data!$C$2:$C$301,$D$1:$O$1) -> 195909 | E10: =SUMIFS(Purchase_Data!$J$2:$J$301,Purchase_Data!$D$2:$D$301,$B$2:$B$11,Purchase_Data!$C$2:$C$301,$D$1:$O$1) -> 175564 | F10: =SUMIFS(Purchase_Data!$J$2:$J$301,Purchase_Data!$D$2:$D$301,$B$2:$B$11,Purchase_Data!$C$2:$C$301,$D$1:$O$1) -> 102849 | G10: =SUMIFS(Purchase_Data!$J$2:$J$301,Purchase_Data!$D$2:$D$301,$B$2:$B$11,Purchase_Data!$C$2:$C$301,$D$1:$O$1) -> 162097 | H10: =SUMIFS(Purchase_Data!$J$2:$J$301,Purchase_Data!$D$2:$D$301,$B$2:$B$11,Purchase_Data!$C$2:$C$301,$D$1:$O$1) -> 151605 | I10: =SUMIFS(Purchase_Data!$J$2:$J$301,Purchase_Data!$D$2:$D$301,$B$2:$B$11,Purchase_Data!$C$2:$C$301,$D$1:$O$1) -> 411751 | J10: =SUMIFS(Purchase_Data!$J$2:$J$301,Purchase_Data!$D$2:$D$301,$B$2:$B$11,Purchase_Data!$C$2:$C$301,$D$1:$O$1) -> 280317 | K10: =SUMIFS(Purchase_Data!$J$2:$J$301,Purchase_Data!$D$2:$D$301,$B$2:$B$11,Purchase_Data!$C$2:$C$301,$D$1:$O$1) -> 87155 | ... O10: =SUMIFS(Purchase_Data!$J$2:$J$301,Purchase_Data!$D$2:$D$301,$B$2:$B$11,Purchase_Data!$C$2:$C$301,$D$1:$O$1) -> 106314
A11: 10 | B11: PepsiCo India | C11: =SUMIF(Purchase_Data!$D$2:$D$301,B11:B20,Purchase_Data!$J$2:$J$301) -> 2049798 | D11: =SUMIFS(Purchase_Data!$J$2:$J$301,Purchase_Data!$D$2:$D$301,$B$2:$B$11,Purchase_Data!$C$2:$C$301,$D$1:$O$1) -> 114170 | E11: =SUMIFS(Purchase_Data!$J$2:$J$301,Purchase_Data!$D$2:$D$301,$B$2:$B$11,Purchase_Data!$C$2:$C$301,$D$1:$O$1) -> 555251 | F11: =SUMIFS(Purchase_Data!$J$2:$J$301,Purchase_Data!$D$2:$D$301,$B$2:$B$11,Purchase_Data!$C$2:$C$301,$D$1:$O$1) -> 252848 | G11: =SUMIFS(Purchase_Data!$J$2:$J$301,Purchase_Data!$D$2:$D$301,$B$2:$B$11,Purchase_Data!$C$2:$C$301,$D$1:$O$1) -> 0 | H11: =SUMIFS(Purchase_Data!$J$2:$J$301,Purchase_Data!$D$2:$D$301,$B$2:$B$11,Purchase_Data!$C$2:$C$301,$D$1:$O$1) -> 142250 | I11: =SUMIFS(Purchase_Data!$J$2:$J$301,Purchase_Data!$D$2:$D$301,$B$2:$B$11,Purchase_Data!$C$2:$C$301,$D$1:$O$1) -> 0 | J11: =SUMIFS(Purchase_Data!$J$2:$J$301,Purchase_Data!$D$2:$D$301,$B$2:$B$11,Purchase_Data!$C$2:$C$301,$D$1:$O$1) -> 0 | K11: =SUMIFS(Purchase_Data!$J$2:$J$301,Purchase_Data!$D$2:$D$301,$B$2:$B$11,Purchase_Data!$C$2:$C$301,$D$1:$O$1) -> 56595 | ... O11: =SUMIFS(Purchase_Data!$J$2:$J$301,Purchase_Data!$D$2:$D$301,$B$2:$B$11,Purchase_Data!$C$2:$C$301,$D$1:$O$1) -> 48068
A16: Sum of Purchase_Amount | B16: Column Labels
A17: Row Labels | B17: January | C17: February | D17: March | E17: April | F17: May | G17: June | H17: July | I17: August | J17: September | K17: October | L17: November | M17: December | N17: Grand Total
A18: Beverages | B18: 107160 | C18: 763350 | D18: 143820 | E18: 424164 | F18: 77294 | G18: 102010 | H18: 339881 | I18: 74501 | J18: 303249 | K18: 574976 | L18: 130218 | M18: 170830 | N18: 3211453
A19: Dairy | B19: 335145 | C19: 749942 | D19: 253802 | E19: 148643 | F19: 235904 | G19: 416872 | H19: 102895 | I19: 232536 | J19: 245734 | K19: 186300 | L19: 322757 | M19: 104804 | N19: 3335334
A20: Decor | B20: 129225 | C20: 300108 | D20: 280425 | E20: 96075 | F20: 170736 | G20: 358015 | H20: 70723 | I20: 130492 | J20: 97638 | K20: 391781 | L20: 566199 | M20: 145896 | N20: 2737313
A21: Handloom | B21: 28420 | C21: 157648 | D21: 170188 | E21: 110631 | F21: 349185 | G21: 469546 | H21: 99264 | I21: 129969 | J21: 162392 | K21: 211620 | L21: 569612 | M21: 40710 | N21: 2499185
A22: Home | B22: 359320 | C22: 284608 | D22: 451361 | E22: 212592 | F22: 584374 | G22: 89539 | H22: 240368 | I22: 18025 | J22: 151332 | K22: 316610 | L22: 161562 | M22: 201348 | N22: 3071039
A23: Kitchen | B23: 263421 | C23: 478399 | E23: 292286 | F23: 214293 | G23: 105549 | H23: 610478 | I23: 433315 | J23: 198049 | K23: 309017 | L23: 209175 | M23: 66384 | N23: 3180366
A24: Snacks | B24: 183477 | C24: 281166 | D24: 99932 | E24: 18724 | F24: 261139 | G24: 111661 | H24: 365893 | I24: 453160 | J24: 173336 | K24: 262114 | L24: 461940 | M24: 99771 | N24: 2772313
A25: Grand Total | B25: 1406168 | C25: 3015221 | D25: 1399528 | E25: 1303115 | F25: 1892925 | G25: 1653192 | H25: 1829502 | I25: 1471998 | J25: 1331730 | K25: 2252418 | L25: 2421463 | M25: 829743 | N25: 20807003
A29: Row Labels | B29: Sum of Purchase_Amount | C29: Sum of Purchase_Amount2
A30: Amul Distributors | B30: 1163176 | C30: 10
A31: Britannia Supply | B31: 2597333 | C31: 2
A32: Coca Cola Supply | B32: 1980707 | C32: 7
A33: HUL Wholesale | B33: 2598468 | C33: 1
A34: ITC Trade Corp | B34: 2093283 | C34: 5
A35: Local Handloom Co | B35: 1729054 | C35: 9
A36: Nestle Partners | B36: 1876719 | C36: 8
A37: PepsiCo India | B37: 2049798 | C37: 6
A38: Regional FMCG Hub | B38: 2566552 | C38: 3
A39: Tata Consumer Trade | B39: 2151913 | C39: 4
A40: Grand Total | B40: 20807003

Sheet Sales Report
A1: Category | B1: Product_Name | C1: Sum of Sales_Amount
A2: Beverages | C2: 547080.26
A3: Dairy | C3: 433373.56
A4: Decor | C4: 554606.46
A5: Handloom | C5: 393258.64
A6: Home | C6: 431291.82
A7: Kitchen | C7: 479474.78
A8: Snacks | C8: 462405.19
A9: Grand Total | C9: 3301490.7
A18: Reciept | B18: Sum of Sales_Amount
A19: Offline | B19: 887949.62
A20: Online | B20: 2413541.1
A21: Grand Total | B21: 3301490.7
A28: Months (Invoice_Date) | B28: Sum of Sales_Amount
A29: Jan | B29: 218485.8
A30: Feb | B30: 379541.42
A31: Mar | B31: 330146.1
A32: Apr | B32: 253611.26
A33: May | B33: 257976.78
A34: Jun | B34: 279961.91
A35: Jul | B35: 200382.08
A36: Aug | B36: 261616.5
A37: Sep | B37: 232860.8
A38: Oct | B38: 311313.67
A39: Nov | B39: 272279.79
A40: Dec | B40: 303314.6
A41: Grand Total | B41: 3301490.7
A46: Month | B46: Quarter
A47: January | B47: Quarter 1
A48: February | B48: Quarter 1
A49: March | B49: Quarter 1
A50: April | B50: Quarter 2
A51: May | B51: Quarter 2
A52: June | B52: Quarter 2
A53: July | B53: Quarter 3
A54: August | B54: Quarter 3
A55: September | B55: Quarter 3
A56: October | B56: Quarter 4
A57: November | B57: Quarter 4
... A69: Row Labels | B69: Sum of Sales_Amount
...

Sheet Purchase Reports
A1: S no | B1: Supplier Name | C1: Amount | D1: January | E1: February | F1: March | G1: April | H1: May | I1: June | J1: July | K1: August | L1: September | M1: October | N1: November | O1: December
A2: 1 | B2: {=_xlfn.UNIQUE(Purchase_Data!D2:D301)} -> #NAME? | C2: {=SUMIF(Purchase_Data!$D$2:$D$301,B2:B11,Purchase_Data!$J$2:$J$301)} -> 0 | D2: {=SUMIFS(Purchase_Data!$J$2:$J$301,Purchase_Data!$D$2:$D$301,B2:B11,Purchase_Data!$C$2:$C$301,D1:O1)} -> 0 | E2: 0 | F2: 0 | G2: 0 | H2: 0 | I2: 0 | J2: 0 | K2: 0 | L2: 0 | M2: 0 | N2: 0 | O2: 0
A3: 2 | B3: #NAME? | C3: 0 | D3: 0 | E3: 0 | F3: 0 | G3: 0 | H3: 0 | I3: 0 | J3: 0 | K3: 0 | L3: 0 | M3: 0 | N3: 0 | O3: 0
A4: 3 | B4: #NAME? | C4: 0 | D4: 0 | E4: 0 | F4: 0 | G4: 0 | H4: 0 | I4: 0 | J4: 0 | K4: 0 | L4: 0 | M4: 0 | N4: 0 | O4: 0
A5: 4 | B5: #NAME? | C5: 0 | D5: 0 | E5: 0 | F5: 0 | G5: 0 | H5: 0 | I5: 0 | J5: 0 | K5: 0 | L5: 0 | M5: 0 | N5: 0 | O5: 0
A6: 5 | B6: #NAME? | C6: 0 | D6: 0 | E6: 0 | F6: 0 | G6: 0 | H6: 0 | I6: 0 | J6: 0 | K6: 0 | L6: 0 | M6: 0 | N6: 0 | O6: 0
A7: 6 | B7: #NAME? | C7: 0 | D7: 0 | E7: 0 | F7: 0 | G7: 0 | H7: 0 | I7: 0 | J7: 0 | K7: 0 | L7: 0 | M7: 0 | N7: 0 | O7: 0
A8: 7 | B8: #NAME? | C8: 0 | D8: 0 | E8: 0 | F8: 0 | G8: 0 | H8: 0 | I8: 0 | J8: 0 | K8: 0 | L8: 0 | M8: 0 | N8: 0 | O8: 0
A9: 8 | B9: #NAME? | C9: 0 | D9: 0 | E9: 0 | F9: 0 | G9: 0 | H9: 0 | I9: 0 | J9: 0 | K9: 0 | L9: 0 | M9: 0 | N9: 0 | O9: 0
A10: 9 | B10: #NAME? | C10: 0 | D10: 0 | E10: 0 | F10: 0 | G10: 0 | H10: 0 | I10: 0 | J10: 0 | K10: 0 | L10: 0 | M10: 0 | N10: 0 | O10: 0
A11: 10 | B11: #NAME? | C11: 0 | D11: 0 | E11: 0 | F11: 0 | G11: 0 | H11: 0 | I11: 0 | J11: 0 | K11: 0 | L11: 0 | M11: 0 | N11: 0 | O11: 0
A22: Sum of Purchase_Amount | B22: Column Labels
A23: Row Labels | B23: January | C23: February | D23: March | E23: April | F23: May | G23: June | H23: July | I23: August | J23: September | K23: October | L23: November | M23: December | N23: Grand Total
A24: Beverages | B24: 107160 | C24: 763350 | D24: 143820 | E24: 424164 | F24: 77294 | G24: 102010 | H24: 339881 | I24: 74501 | J24: 303249 | K24: 574976 | L24: 130218 | M24: 170830 | N24: 3211453
A25: Dairy | B25: 335145 | C25: 749942 | D25: 253802 | E25: 148643 | F25: 235904 | G25: 416872 | H25: 102895 | I25: 232536 | J25: 245734 | K25: 186300 | L25: 322757 | M25: 104804 | N25: 3335334
A26: Decor | B26: 129225 | C26: 300108 | D26: 280425 | E26: 96075 | F26: 170736 | G26: 358015 | H26: 70723 | I26: 130492 | J26: 97638 | K26: 391781 | L26: 566199 | M26: 145896 | N26: 2737313
A27: Handloom | B27: 28420 | C27: 157648 | D27: 170188 | E27: 110631 | F27: 349185 | G27: 469546 | H27: 99264 | I27: 129969 | J27: 162392 | K27: 211620 | L27: 569612 | M27: 40710 | N27: 2499185
A28: Home | B28: 359320 | C28: 284608 | D28: 451361 | E28: 212592 | F28: 584374 | G28: 89539 | H28: 240368 | I28: 18025 | J28: 151332 | K28: 316610 | L28: 161562 | M28: 201348 | N28: 3071039
A29: Kitchen | B29: 263421 | C29: 478399 | E29: 292286 | F29: 214293 | G29: 105549 | H29: 610478 | I29: 433315 | J29: 198049 | K29: 309017 | L29: 209175 | M29: 66384 | N29: 3180366
A30: Snacks | B30: 183477 | C30: 281166 | D30: 99932 | E30: 18724 | F30: 261139 | G30: 111661 | H30: 365893 | I30: 453160 | J30: 173336 | K30: 262114 | L30: 461940 | M30: 99771 | N30: 2772313
A31: Grand Total | B31: 1406168 | C31: 3015221 | D31: 1399528 | E31: 1303115 | F31: 1892925 | G31: 1653192 | H31: 1829502 | I31: 1471998 | J31: 1331730 | K31: 2252418 | L31: 2421463 | M31: 829743 | N31: 20807003
A37: Row Labels | B37: Sum of Purchase_Amount | C37: Sum of Purchase_Amount2
A38: Amul Distributors | B38: 1163176 | C38: 10
A39: Britannia Supply | B39: 2597333 | C39: 2
A40: Coca Cola Supply | B40: 1980707 | C40: 7
A41: HUL Wholesale | B41: 2598468 | C41: 1
A42: ITC Trade Corp | B42: 2093283 | C42: 5
A43: Local Handloom Co | B43: 1729054 | C43: 9
A44: Nestle Partners | B44: 1876719 | C44: 8
A45: PepsiCo India | B45: 2049798 | C45: 6
A46: Regional FMCG Hub | B46: 2566552 | C46: 3
A47: Tata Consumer Trade | B47: 2151913 | C47: 4
A48: Grand Total | B48: 20807003

Sheet KPI
T1: Row Labels | U1: Sum of Sales_Amount
A2: =GETPIVOTDATA("[Measures].[Sum of Sales_Amount]",$A$3) -> 3301490.7 | C2: =GETPIVOTDATA("[Measures].[Sum of Purchase_Amount]",$C$3) -> 20807003 | E2: =E4 -> -17505512 | T2: Offline | U2: 887949.62
A3: Sum of Sales_Amount | C3: Sum of Purchase_Amount | E3: Loss | G3: Row Labels | H3: Sum of Sales_Amount | K3: Row Labels | L3: Sum of Sales_Amount | O3: Row Labels | P3: Sum of Sales_Amount | T3: Online | U3: 2413541.1
A4: 3301490.7 | C4: 20807003 | E4: =GETPIVOTDATA("[Measures].[Sum of Sales_Amount]",$A$3)-GETPIVOTDATA("[Measures].[Sum of Purchase_Amount]",$C$3) -> -17505512 | G4: January | H4: 218485.8 | K4: Delhi | L4: 722608.36 | O4: Biscuits | P4: 75665.28 | T4: Grand Total | U4: 3301490.7
G5: February | H5: 379541.42 | K5: Faridabad | L5: 623712.09 | O5: Butter 100g | P5: 116122.94
G6: March | H6: 330146.1 | K6: Ghaziabad | L6: 658651.69 | O6: Cheese Slices | P6: 98596.96
G7: April | H7: 253611.26 | K7: Gurugram | L7: 596296.44 | O7: Cola 1L | P7: 160311.15
G8: May | H8: 257976.78 | K8: Noida | L8: 700222.13 | O8: Cookies | P8: 139881.33
G9: June | H9: 279961.91 | K9: Grand Total | L9: 3301490.7 | O9: Cooking Oil 1L | P9: 112191.02
G10: July | H10: 200382.08 | O10: Cotton Bedsheet | P10: 127420.11
G11: August | H11: 261616.5 | O11: Curd 500g | P11: 88282.88
G12: September | H12: 232860.8 | O12: Detergent 1kg | P12: 168591.24
G13: October | H13: 311313.67 | K13: =K3 -> Row Labels | L13: =L3 -> Sum of Sales_Amount | O13: Dishwash Liquid | P13: 151591.67
G14: November | H14: 272279.79 | K14: =K4 -> Delhi | L14: =L4 -> 722608.36 | O14: Energy Drink | P14: 137487.37
G15: December | H15: 303314.6 | K15: =K5 -> Faridabad | L15: =L5 -> 623712.09 | O15: Floor Cleaner | P15: 111108.91
G16: Grand Total | H16: 3301490.7 | K16: =K6 -> Ghaziabad | L16: =L6 -> 658651.69 | O16: Hand Towel | P16: 57427.7
K17: =K7 -> Gurugram | L17: =L7 -> 596296.44 | O17: Juice Pack | P17: 111264.81
K18: =K8 -> Noida | L18: =L8 -> 700222.13 | O18: Lamp | P18: 243374.86
K19: =K9 -> Grand Total | L19: =L9 -> 3301490.7 | O19: Milk 1L | P19: 130370.78
K20: =K10 -> 0 | L20: =L10 -> 0 | O20: Namkeen Mix | P20: 105550.17
O21: Potato Chips | P21: 141308.41
O22: Rice 5kg | P22: 83691.92
O23: Spices Pack | P23: 89000.18
O24: Table Runner | P24: 208410.83
O25: Table Vase | P25: 171507.77
O26: Tea 250g | P26: 138016.93
O27: Wall Frame | P27: 139723.83
O28: Wheat Flour 5kg | P28: 194591.66
O29: Grand Total | P29: 3301490.7
O33: =O3 -> Row Labels | P33: =P3 -> Sum of Sales_Amount
O34: =O4 -> Biscuits | P34: =P4 -> 75665.28
O35: =O5 -> Butter 100g | P35: =P5 -> 116122.94
O36: =O6 -> Cheese Slices | P36: =P6 -> 98596.96
O37: =O7 -> Cola 1L | P37: =P7 -> 160311.15
O38: =O8 -> Cookies | P38: =P8 -> 139881.33
O39: =O9 -> Cooking Oil 1L | P39: =P9 -> 112191.02
O40: =O10 -> Cotton Bedsheet | P40: =P10 -> 127420.11
O41: =O11 -> Curd 500g | P41: =P11 -> 88282.88
O42: =O12 -> Detergent 1kg | P42: =P12 -> 168591.24
O43: =O13 -> Dishwash Liquid | P43: =P13 -> 151591.67
...

Sheet Dashboard

Sheet KPI Practice
A2: =GETPIVOTDATA("[Measures].[Sum of Sales_Amount]",$A$3) -> 3301490.7 | C2: =GETPIVOTDATA("[Measures].[Sum of Purchase_Amount]",$C$3) -> 20807003 | E2: =E4 -> -17505512
A3: Sum of Sales_Amount | C3: Sum of Purchase_Amount | E3: Loss | G3: Row Labels | H3: Sum of Sales_Amount | J3: Row Labels | K3: Sum of Sales_Amount | M3: Row Labels | N3: Sum of Sales_Amount | P3: Row Labels | Q3: Sum of Sales_Amount
A4: 3301490.7 | C4: 20807003 | E4: =GETPIVOTDATA("[Measures].[Sum of Sales_Amount]",$A$3)-GETPIVOTDATA("[Measures].[Sum of Purchase_Amount]",$C$3) -> -17505512 | G4: January | H4: 218485.8 | J4: Delhi | K4: 722608.36 | M4: Biscuits | N4: 75665.28 | P4: Offline | Q4: 887949.62
G5: February | H5: 379541.42 | J5: Faridabad | K5: 623712.09 | M5: Butter 100g | N5: 116122.94 | P5: Online | Q5: 2413541.1
G6: March | H6: 330146.1 | J6: Ghaziabad | K6: 658651.69 | M6: Cheese Slices | N6: 98596.96 | P6: Grand Total | Q6: 3301490.7
G7: April | H7: 253611.26 | J7: Gurugram | K7: 596296.44 | M7: Cola 1L | N7: 160311.15
G8: May | H8: 257976.78 | J8: Noida | K8: 700222.13 | M8: Cookies | N8: 139881.33
G9: June | H9: 279961.91 | J9: Grand Total | K9: 3301490.7 | M9: Cooking Oil 1L | N9: 112191.02
G10: July | H10: 200382.08 | M10: Cotton Bedsheet | N10: 127420.11
G11: August | H11: 261616.5 | M11: Curd 500g | N11: 88282.88
G12: September | H12: 232860.8 | M12: Detergent 1kg | N12: 168591.24
G13: October | H13: 311313.67 | M13: Dishwash Liquid | N13: 151591.67
G14: November | H14: 272279.79 | M14: Energy Drink | N14: 137487.37
G15: December | H15: 303314.6 | M15: Floor Cleaner | N15: 111108.91
G16: Grand Total | H16: 3301490.7 | M16: Hand Towel | N16: 57427.7
M17: Juice Pack | N17: 111264.81
M18: Lamp | N18: 243374.86
M19: Milk 1L | N19: 130370.78
M20: Namkeen Mix | N20: 105550.17
M21: Potato Chips | N21: 141308.41
M22: Rice 5kg | N22: 83691.92
M23: Spices Pack | N23: 89000.18
M24: Table Runner | N24: 208410.83
M25: Table Vase | N25: 171507.77
M26: Tea 250g | N26: 138016.93
M27: Wall Frame | N27: 139723.83
M28: Wheat Flour 5kg | N28: 194591.66
M29: Grand Total | N29: 3301490.7
M33: =M3 -> Row Labels | N33: =N3 -> Sum of Sales_Amount
M34: =M4 -> Biscuits | N34: =N4 -> 75665.28
M35: =M5 -> Butter 100g | N35: =N5 -> 116122.94
M36: =M6 -> Cheese Slices | N36: =N6 -> 98596.96
M37: =M7 -> Cola 1L | N37: =N7 -> 160311.15
M38: =M8 -> Cookies | N38: =N8 -> 139881.33
M39: =M9 -> Cooking Oil 1L | N39: =N9 -> 112191.02
M40: =M10 -> Cotton Bedsheet | N40: =N10 -> 127420.11
M41: =M11 -> Curd 500g | N41: =N11 -> 88282.88
M42: =M12 -> Detergent 1kg | N42: =N12 -> 168591.24
M43: =M13 -> Dishwash Liquid | N43: =N13 -> 151591.67
M44: =M14 -> Energy Drink | N44: =N14 -> 137487.37
...

Sheet Dashboard Practice
AC19: x

Sheet Sales_Data
A1: Invoice_No | B1: Invoice_Date | C1: Month | D1: Quarter | E1: Customer_Name | F1: City | G1: Category | H1: Product_Name | I1: Reciept | J1: Quantity_Sold | K1: Sale_Rate | L1: Sales_Amount
A2: S00001 | B2: 45532 | C2: =TEXT(B2,"mmmm") -> August | D2: =VLOOKUP(C2,'Sales Report'!$A$47:$B$58,2,FALSE) -> Quarter 3 | E2: Retailer_114 | F2: Noida | G2: Kitchen | H2: Rice 5kg | I2: Offline | J2: 11 | K2: 112.01 | L2: 1232.11
A3: S00002 | B3: 45329 | C3: =TEXT(B3,"mmmm") -> February | D3: =VLOOKUP(C3,'Sales Report'!$A$47:$B$58,2,FALSE) -> Quarter 1 | E3: Retailer_80 | F3: Faridabad | G3: Handloom | H3: Hand Towel | I3: Online | J3: 19 | K3: 54.71 | L3: 1039.49
A4: S00003 | B4: 45331 | C4: =TEXT(B4,"mmmm") -> February | D4: =VLOOKUP(C4,'Sales Report'!$A$47:$B$58,2,FALSE) -> Quarter 1 | E4: Retailer_24 | F4: Ghaziabad | G4: Kitchen | H4: Cooking Oil 1L | I4: Online | J4: 2 | K4: 254.05 | L4: 508.1
A5: S00004 | B5: 45313 | C5: =TEXT(B5,"mmmm") -> January | D5: =VLOOKUP(C5,'Sales Report'!$A$47:$B$58,2,FALSE) -> Quarter 1 | E5: Retailer_116 | F5: Ghaziabad | G5: Home | H5: Dishwash Liquid | I5: Online | J5: 13 | K5: 301.74 | L5: 3922.62
A6: S00005 | B6: 45369 | C6: =TEXT(B6,"mmmm") -> March | D6: =VLOOKUP(C6,'Sales Report'!$A$47:$B$58,2,FALSE) -> Quarter 1 | E6: Retailer_16 | F6: Faridabad | G6: Decor | H6: Wall Frame | I6: Online | J6: 11 | K6: 381.92 | L6: 4201.12
A7: S00006 | B7: 45312 | C7: =TEXT(B7,"mmmm") -> January | D7: =VLOOKUP(C7,'Sales Report'!$A$47:$B$58,2,FALSE) -> Quarter 1 | E7: Retailer_64 | F7: Faridabad | G7: Dairy | H7: Butter 100g | I7: Offline | J7: 3 | K7: 330.78 | L7: 992.34
A8: S00007 | B8: 45490 | C8: =TEXT(B8,"mmmm") -> July | D8: =VLOOKUP(C8,'Sales Report'!$A$47:$B$58,2,FALSE) -> Quarter 3 | E8: Retailer_105 | F8: Noida | G8: Kitchen | H8: Spices Pack | I8: Offline | J8: 12 | K8: 259.57 | L8: 3114.84
A9: S00008 | B9: 45463 | C9: =TEXT(B9,"mmmm") -> June | D9: =VLOOKUP(C9,'Sales Report'!$A$47:$B$58,2,FALSE) -> Quarter 2 | E9: Retailer_17 | F9: Noida | G9: Decor | H9: Lamp | I9: Online | J9: 2 | K9: 503.39 | L9: 1006.78
A10: S00009 | B10: 45628 | C10: =TEXT(B10,"mmmm") -> December | D10: =VLOOKUP(C10,'Sales Report'!$A$47:$B$58,2,FALSE) -> Quarter 4 | E10: Retailer_39 | F10: Noida | G10: Dairy | H10: Cheese Slices | I10: Online | J10: 10 | K10: 179.25 | L10: 1792.5
A11: S00010 | B11: 45649 | C11: =TEXT(B11,"mmmm") -> December | D11: =VLOOKUP(C11,'Sales Report'!$A$47:$B$58,2,FALSE) -> Quarter 4 | E11: Retailer_101 | F11: Gurugram | G11: Dairy | H11: Curd 500g | I11: Online | J11: 12 | K11: 221.52 | L11: 2658.24
A12: S00011 | B12: 45621 | C12: =TEXT(B12,"mmmm") -> November | D12: =VLOOKUP(C12,'Sales Report'!$A$47:$B$58,2,FALSE) -> Quarter 4 | E12: Retailer_85 | F12: Gurugram | G12: Home | H12: Dishwash Liquid | I12: Online | J12: 3 | K12: 209.15 | L12: 627.45
A13: S00012 | B13: 45508 | C13: =TEXT(B13,"mmmm") -> August | D13: =VLOOKUP(C13,'Sales Report'!$A$47:$B$58,2,FALSE) -> Quarter 3 | E13: Retailer_131 | F13: Noida | G13: Decor | H13: Lamp | I13: Offline | J13: 17 | K13: 79.72 | L13: 1355.24
... A1001: S01000 | B1001: 45516 | C1001: =TEXT(B1001,"mmmm") -> August | D1001: =VLOOKUP(C1001,'Sales Report'!$A$47:$B$58,2,FALSE) -> Quarter 3 | E1001: Retailer_25 | F1001: Faridabad | G1001: Handloom | H1001: Cotton Bedsheet | I1001: Online | J1001: 3 | K1001: 492.89 | L1001: 1478.67

Sheet Sales Manual Reports
A4: Category | B4: Product_Name | C4: Sum of Sales_Amount
A5: Beverages | C5: 547080.26
A6: Dairy | C6: 433373.56
A7: Decor | C7: 554606.46
A8: Handloom | C8: 393258.64
A9: Home | C9: 431291.82
A10: Kitchen | C10: 479474.78
A11: Snacks | C11: 462405.19
A12: Grand Total | C12: 3301490.7
A18: Reciept | B18: Sum of Sales_Amount
A19: Offline | B19: 887949.62
A20: Online | B20: 2413541.1
A21: Grand Total | B21: 3301490.7
A25: Quarter | B25: Month | C25: Sum of Sales_Amount
A26: Quarter 1 | B26: January | C26: 218485.8
B27: February | C27: 379541.42
B28: March | C28: 330146.1
A29: Quarter 1 Total | C29: 928173.32
A30: Quarter 2 | B30: April | C30: 253611.26
B31: May | C31: 257976.78
B32: June | C32: 279961.91
A33: Quarter 2 Total | C33: 791549.95
A34: Quarter 3 | B34: July | C34: 200382.08 | F34: Month | G34: Quarter
B35: August | C35: 261616.5 | F35: January | G35: Quarter 1
B36: September | C36: 232860.8 | F36: February | G36: Quarter 1
A37: Quarter 3 Total | C37: 694859.38 | F37: March | G37: Quarter 1
A38: Quarter 4 | B38: October | C38: 311313.67 | F38: April | G38: Quarter 2
B39: November | C39: 272279.79 | F39: May | G39: Quarter 2
B40: December | C40: 303314.6 | F40: June | G40: Quarter 2
A41: Quarter 4 Total | C41: 886908.06 | F41: July | G41: Quarter 3
A42: Grand Total | C42: 3301490.7 | F42: August | G42: Quarter 3
F43: September | G43: Quarter 3
F44: October | G44: Quarter 4
F45: November | G45: Quarter 4
F46: December | G46: Quarter 4

Sheet Planning
C3: Invoice_No
C4: Invoice_Date
C5: Month
C6: Quarter
C7: Customer_Name
C8: City
C9: Category
C10: Product_Name
C11: Reciept
C12: Quantity_Sold
C13: Sale_Rate
C14: Sales_Amount

Sheet Theory
